Workbook

Sheet ToDo
B2: Check blue tabs - all others are from BIM Landscape - for reference and further validation. Calculations not yet working!
B4: GIS-Standards | C4: Following "BIM Landscape" columns with some additions/clarifications (check column comments)
C6: ToDo-s | M6: Responsible | N6: Status
D7: EN/ISO standards included (Geographic information), ca 90 standards | M7: Raido | N7: Done
D8: EN/ISO standards ("BIM"+"GIS"), +25 standards | M8: Raido | N8: Done
D9: Suggest additional GIS related sources to be included? | M9: ???
E10: Source #1 | M10: ???
E11: Source #2 | M11: ???
D12: Keywords/subdomain extractions from abstract/scope? | M12: ???
B17: GIS-Relationships | C17: Following "BIM Landscape" columns with some additions/clarifications (check column comments)
C19: ToDo-s | M19: Responsible | N19: Status
D20: EN/ISO standards references (Geographic information) (normative/informative) | M20: Raido | N20: Done
D21: EN/ISO standards ("BIM"+"GIS") (normative/informative) | M21: Raido | N21: Done
M22: ???
M23: ???
M24: ???
B26: Deliverable | C26: Article structure, data visualization possibilities
C28: ToDo-s | M28: Responsible | N28: Status
D29: Structure and introductory parts for a future article (How BIM and GIS standards interrelates with each other) | M29: Raido | N29: Not started
D30: Data visualization (ex. | F30: https://gephi.org/ - is it good enough for our workflows?) | M30: ???
E31: neo4j - commerical? (if someone has access?)
E32: Any other tool for visualization?
E33: What additional columns are needed in this Excel?
D34: Building up tables with calculated key values (currently most of them are N/A) | M34: Raido | N34: Not started
E35: To use BIM Landscape values or …
D36: How to find connections to BIM Landscape Explorer - in terms of standards
E37: ISO ICS groups | M37: Raido | N37: Not started
E38: ???
D39: BIM (Level of Information need - apperance etc) vs GIS

Sheet GIS-Standards
A1: ID | B1: Standard Number | C1: Title | D1: Scope/Abstract | E1: Comment | F1: Web Links | G1: First Year | H1: Current Year | I1: AC Year | J1: ICS | K1: Type | L1: Is CEN? | M1: CEN Committee | N1: Is ISO? | O1: ISO Committee | P1: Colour_Type_calculation | Q1: Degree Centrality | R1: In-Degree Centrality | S1: Out-Degree Centrality | T1: Eigencentrality
A2: 1 | B2: CEN/TR 15449-1 | C2: Geographic information - Spatial data infrastructures - Part 1: Reference model | D2: This part of the Technical Report provides a reference model for a Spatial Data Infrastructure (SDI). It covers framework standards and identifies the relevant standards, technical specifications, technical reports and guidelines. This part of the Technical Report provides a context model for the other parts of this Technical Report applying general architecture standards. The intended readership of this Technical Report are those people who are responsible for creating frameworks for SDIs, experts contributing to INSPIRE, experts in information and communication technologies and e-government that need to familiarise themselves with geographic information and SDI concepts, and standards developers and writers. | F2: https://www.en-standard.eu/pd-cen-tr-15449-1-2012-geographic-information-spatial-data-infrastructures-reference-model/ | G2: 2012.10 | H2: 2012.10 | J2: 35.240.70; 07.040 | L2: Yes | M2: CEN/TC 287 | N2: No | P2: =INDEX(Colours!$C$2:$C$14,MATCH(K2,Colours!$A$2:$A$14,0)) -> #N/A | T2: =3+TableStandards11[[#This Row],[Degree Centrality]]*17 -> 3
A3: 2 | B3: CEN/TR 15449-2 | C3: Geographic information - Spatial data infrastructures - Part 2: Best practices | D3: This part of the Technical Report provides best practices regarding Spatial Data Infrastructures (SDIs), referencing to the outcomes of the projects in the frame of the European Union funding programmes. It summarises the deliverables of projects, structured according to the reference model defined in Part 1 of this Technical Report, to be made available in an on-line repository where the relevant outcomes are collected and classified in order to provide a structured sets of recommendations for implementing SDIs at the European, national and sub-national levels. This collection refers mainly to the projects funded by the European Union funding programmes: this choice is driven by the wide vision and analysis which such kind of projects can provide and the wide numbers of stakeholders which have been involved. The outcomes delivered by these relevant practices are collected into a document registry available through the CEN/TC 287 web site. This part of the Technical Report defines the processes and the content of these projects and documents registries, which will help making them more accessible and re-usable. It provides the relevant project deliverables addressing the main SDI issues as described in the other parts of this Technical Report. The intended readership of this Technical Report are those people who are responsible for creating frameworks for SDI, experts contributing to INSPIRE, experts in information and communication technologies and e-government that need to familiarize themselves with geographic information and SDI concepts, and standards developers and writers. | F3: https://www.en-standard.eu/pd-cen-tr-15449-2-2012-geographic-information-spatial-data-infrastructures-best-practices/ | G3: 2012.10 | H3: 2012.10 | J3: 35.240.70; 07.040 | L3: Yes | M3: CEN/TC 287 | N3: No | P3: =INDEX(Colours!$C$2:$C$14,MATCH(K3,Colours!$A$2:$A$14,0)) -> #N/A | T3: =3+TableStandards11[[#This Row],[Degree Centrality]]*17 -> 3
A4: 3 | B4: CEN/TR 15449-3 | C4: Geographic information - Spatial data infrastructures - Part 3: Data centric view | D4: Part 3 of the Technical Report describes a data-centric view of a Spatial Data Infrastructure (SDI). The Data Centric view addresses the concepts of semantic interoperability, the methodology for developing data specifications through the application of the relevant International Standards, and the content of such specifications including Application Schemas, Feature Catalogues, General Feature Model, Data Lifecycle Management and Data Quality, Data Access and Data Transformation. The intended readership of this Technical Report are those people who are responsible for creating frameworks for SDI, experts contributing to INSPIRE, experts in information and communication technologies and e-government that need to familiarise themselves with geographic information and SDI concepts, and standards developers and writers. | F4: https://www.en-standard.eu/pd-cen-tr-15449-3-2012-geographic-information-spatial-data-infrastructures-data-centric-view/ | G4: 2012.10 | H4: 2012.10 | J4: 35.240.70; 07.040 | L4: Yes | M4: CEN/TC 287 | N4: No | P4: =INDEX(Colours!$C$2:$C$14,MATCH(K4,Colours!$A$2:$A$14,0)) -> #N/A | T4: =3+TableStandards11[[#This Row],[Degree Centrality]]*17 -> 3
A5: 4 | B5: CEN/TR 15449-4 | C5: Geographic information - Spatial Data Infrastructure - Service centric view | D5: This Technical Report describes a service-centric view of a Spatial Data Infrastructure (SDI). The Service Centric view addresses the concepts of service specifications, the methodology for developing service specifications through the application of the relevant International Standards, and the content of such service specifications described from the perspective of the five Reference Model of Open Distributed Processing (RM-ODP) viewpoints: the enterprise viewpoint addresses service aspects from an organisational, business and user perspective; the computational viewpoint addresses service aspects from a system architect perspective; the information viewpoint addresses service aspects from a geospatial information expert perspective; the engineering viewpoint addresses service aspects from a system designer perspective; the technology viewpoint addresses service aspects from a system builder and implementer perspective. The intended readership of this Technical Report is those people who are responsible for creating frameworks for SDI, experts contributing to INSPIRE experts in information and communication technologies and e-government that need to familiarise themselves with geographic information and SDI concepts, and standards developers and writers. | F5: https://www.en-standard.eu/pd-cen-tr-15449-4-2013-geographic-information-spatial-data-infrastructure-service-centric-view/ | G5: 2013.07 | H5: 2013.07 | J5: 35.240.70 | L5: Yes | M5: CEN/TC 287 | N5: No | P5: =INDEX(Colours!$C$2:$C$14,MATCH(K5,Colours!$A$2:$A$14,0)) -> #N/A | T5: =3+TableStandards11[[#This Row],[Degree Centrality]]*17 -> 3
A6: 5 | B6: CEN/TR 15449-5 | C6: Geographic information - Spatial data infrastructures - Part 5: Validation and testing | D6: This part of the Technical Report provides guidance for validation and testing of data, metadata and services, as the main Spatial Data Infrastructure (SDI) components defined in other parts of CEN/TR 15449. The guidance is given by means of examples of the validation and testing process required to assure conformance with the requirements existing in the relevant standards and guidelines. | F6: n/a | G6: 2015.04 | H6: 2015.04 | J6: 35.240.70; 07.040 | L6: Yes | M6: CEN/TC 287 | N6: No | P6: =INDEX(Colours!$C$2:$C$14,MATCH(K6,Colours!$A$2:$A$14,0)) -> #N/A | T6: =3+TableStandards11[[#This Row],[Degree Centrality]]*17 -> 3
A7: 6 | B7: ISO 15686-1 | C7: Buildings and constructed assets -- Service life planning -- Part 1: General principles and framework | D7: This part of ISO 15686 identifies and establishes general principles for service life planning and a systematic framework for undertaking service life planning of a planned building or construction work throughout its life cycle (or remaining life cycle for existing buildings or construction works). The life cycle incorporates initiation, project definition, design, construction, commissioning, operation, maintenance, refurbishment, replacement, deconstruction and ultimate disposal, recycling or re-use of the asset (or parts thereof), including its components, systems and building services. This part of ISO 15686 is applicable to the service life planning of individual buildings. NOTE A series of service life plans can be used as input data to the strategic property management of a number of buildings. | E7: BIM + GIS | F7: https://www.iso.org/standard/45798.html | G7: 2000.09 | H7: 2011.05 | J7: 91.040.01 | L7: No | M7: n/a | N7: Yes | O7: ISO/TC 59 | P7: =INDEX(Colours!$C$2:$C$14,MATCH(K7,Colours!$A$2:$A$14,0)) -> #N/A | T7: =3+TableStandards11[[#This Row],[Degree Centrality]]*17 -> 3
A8: 7 | B8: ISO 15686-10 | C8: Buildings and constructed assets -- Service life planning -- Part 10: When to assess functional performance | D8: This part of ISO 15686 establishes when to specify or verify functional performance requirements during the service life of buildings and building-related facilities, and when to check the capability of buildings and facilities to meet identified requirements.1) This part of ISO 15686 is applicable to any scope of holdings, whether a set (or portfolio) of buildings, a single building (large or small) or a facility which is part of a building (such as one group of spaces, one floor or several floors). It is applicable to the range of roles of stakeholders, from the owners and managers to the occupants, tenants or other users. It is intended to be used with ISO 15686-1, ISO 15686-2, ISO 15686-3, ISO 15686-5, ISO 15686-6, ISO 15686-7, ISO 15686-8 and ISO 15686-9. NOTE 1 The principles and methods can be applied to a single-family residence, but this part of ISO 15686 calls for greater frequency and extent of assessing demand and supply than is typically appropriate.2) NOTE 2 The application of this part of ISO 15686 can be required by the client or by any entity having authority, including regulatory authority. NOTE 3 In Table 2, the column entitled “Outputs called for by other parts of ISO 15686” is provided to show how outputs from other parts of ISO 15686 occur at each phase, whether or not this part of ISO 15686 requires action or output. | E8: BIM + GIS | F8: https://www.iso.org/standard/44859.html | G8: 2010.06 | H8: 2010.06 | J8: 91.040.01 | L8: No | M8: n/a | N8: Yes | O8: ISO/TC 59/SC 14 | P8: =INDEX(Colours!$C$2:$C$14,MATCH(K8,Colours!$A$2:$A$14,0)) -> #N/A | T8: =3+TableStandards11[[#This Row],[Degree Centrality]]*17 -> 3
A9: 8 | B9: ISO 15686-4 | C9: Building Construction -- Service Life Planning -- Part 4: Service Life Planning using Building Information Modelling | D9: This part of ISO 15686 provides information and guidance on the use of standards for information exchange for service life planning of buildings and constructed assets and their components as well as the required supporting data. It provides guidance on structuring information from existing data sources to enable delivery of their information content in a structure that conforms to international standards for information exchange. In particular, reference is made to ISO 16739. The Construction Operations Building Information Exchange (COBie) standard for the exchange of facility information in tabular data are used as an alternative representation. COBie is a tabular representation of a handover view of the IFC schema. It is also applicable to the exchange of service life information between categories of design and information management software applications that have standards-based information exchange interfaces including: a) Building construction Information Modelling (BIM); b) Computer Aided Facilities Management (CAFM). Excluded from this part of the standard are — information exchange using proprietary methods, and — processing and analysis of data within individual software applications, though examples are provided. The main target audience is the Information manager who will use the framework to assist in structuring the International, national or project/facility level BIM guidance document. This Standard specifies the structure and representation of service life data. It is focused on key exchange requirements underlying the common transactions. This document may be used for a variety of purposes a) to achieve and maintain a common understanding within the national and project contexts; b) to establish the desired outcomes and to define appropriate quality; c) to identify appropriate management effort and tools; d) to identify necessary effort and resourcing. Service life planning involves the application of data about elements within a building or constructed assets to enable their design, predicted or estimated service life to be determined and communicated. Buildings are increasingly designed using Building Information Modelling (BIM), an approach that can provide a specification of all the objects in building and how they are aggregated into parts, assemblies and systems. An architect or engineer can define the objects using BIM; it is anticipated that the actor having the service life planning role will apply service life data to these objects and make the data available for other purposes through the use of data exchange standards. Using information exchange standards to describe the structure of service life planning information is important because it normalizes the way in which service life information should be delivered from source to user so that relevant different attributes can be exchanged and a range of software applications can be used to capture the information. | E9: BIM + GIS | F9: https://www.iso.org/standard/59150.html | G9: 2014.01 | H9: 2014.01 | J9: 91.040.01 | L9: No | M9: n/a | N9: Yes | O9: ISO/TC 59/SC 14 | P9: =INDEX(Colours!$C$2:$C$14,MATCH(K9,Colours!$A$2:$A$14,0)) -> #N/A | T9: =3+TableStandards11[[#This Row],[Degree Centrality]]*17 -> 3
A10: 9 | B10: ISO 15686-7 | C10: Buildings and constructed assets -- Service life planning -- Part 7: Performance evaluation for feedback of service life data from practice | D10: This document provides a generic basis for performance evaluation for feedback of service life data from existing buildings and constructed assets, including a definition of the terms to be used and the description of how the (technical) performance can be described and documented to ensure consistencies. The purpose of this document is to describe the principles for service life performance surveys and evaluation with an emphasis on technical recommendations. It describes a generic methodology, including the terms to be used, that provides guidance on the planning, documentation and inspection phases, as well as on analysis and interpretation of performance evaluations, both on the object (single building) and network (stock of buildings) level. While maintenance planning is outside the scope of this document, maintenance-driven inspections and subsequent recommended actions could have significant effects upon service life and performance. | E10: BIM + GIS | F10: https://www.iso.org/standard/61149.html | G10: 2006.03 | H10: 2017.04 | J10: 91.040.01 | L10: No | M10: n/a | N10: Yes | O10: ISO/TC 59/SC 14 | P10: =INDEX(Colours!$C$2:$C$14,MATCH(K10,Colours!$A$2:$A$14,0)) -> #N/A | T10: =3+TableStandards11[[#This Row],[Degree Centrality]]*17 -> 3
A11: 10 | B11: ISO 19101-1 | C11: Geographic information - Reference model - Part 1: Fundamentals | D11: This part of ISO 19101 defines the reference model for standardization in the field of geographic information. This reference model describes the notion of interoperability and sets forth the fundamentals by which this standardization takes place. Although structured in the context of information technology and information technology standards, this part of ISO 19101 is independent of any application development method or technology implementation approach. | F11: https://www.iso.org/standard/59164.html | G11: 2005.01 | H11: 2014.11 | J11: 35.240.70 | L11: Yes | M11: CEN/TC 287 | N11: Yes | O11: ISO/TC 211 | P11: =INDEX(Colours!$C$2:$C$14,MATCH(K11,Colours!$A$2:$A$14,0)) -> #N/A | T11: =3+TableStandards11[[#This Row],[Degree Centrality]]*17 -> 3
A12: 11 | B12: ISO 19101-2 | C12: Geographic information -- Reference model -- Part 2: Imagery | D12: This document defines a reference model for standardization in the field of geographic imagery processing. This reference model identifies the scope of the standardization activity being undertaken and the context in which it takes place. The reference model includes gridded data with an emphasis on imagery. Although structured in the context of information technology and information technology standards, this document is independent of any application development method or technology implementation approach. | F12: https://www.iso.org/standard/69325.html | G12: 2008.06 | H12: 2018.05 | J12: 35.240.70 | L12: No | M12: n/a | N12: Yes | O12: ISO/TC 211 | P12: =INDEX(Colours!$C$2:$C$14,MATCH(K12,Colours!$A$2:$A$14,0)) -> #N/A | T12: =3+TableStandards11[[#This Row],[Degree Centrality]]*17 -> 3
A13: 12 | B13: ISO 19103 | C13: Geographic information - Conceptual schema language | D13: This document specifies provisions for the use of a conceptual schema language within the context of modelling geographic information. The chosen conceptual schema language is a subset of the Unified Modeling Language (UML). This document specifies a UML profile for modelling geographic information. This document specifies a set of core data types for use in conceptual schemas. The standardization target type of this document is conceptual schemas describing geographic information. | F13: https://www.iso.org/standard/83454.html | G13: 2024.10 | H13: 2024.10 | J13: 35.240.70 | L13: Yes | M13: CEN/TC 287 | N13: Yes | O13: ISO/TC 211 | P13: =INDEX(Colours!$C$2:$C$14,MATCH(K13,Colours!$A$2:$A$14,0)) -> #N/A | T13: =3+TableStandards11[[#This Row],[Degree Centrality]]*17 -> 3
A14: 13 | B14: ISO 19104 | C14: Geographic information -- Terminology | D14: ISO 19104:2016 specifies requirements for the collection, management and publication of terminology in the field of geographic information. The scope of this document includes - selection of concepts, harmonization of concepts and development of concept systems, - structure and content of terminological entries, - term selection, - definition preparation, - cultural and linguistic adaptation, - layout and formatting requirements in rendered documents, and - establishment and management of terminology registers. ISO 19104:2016 is applicable to International Standards and Technical Specifications in the field of geographic information. | F14: https://www.iso.org/standard/63541.html | G14: 2008.11 | H14: 2016.10 | J14: 35.240.70; 01.040.35 | L14: No | M14: n/a | N14: Yes | O14: ISO/TC 211 | P14: =INDEX(Colours!$C$2:$C$14,MATCH(K14,Colours!$A$2:$A$14,0)) -> #N/A | T14: =3+TableStandards11[[#This Row],[Degree Centrality]]*17 -> 3
A15: 14 | B15: ISO 19105 | C15: Geographic information - Conformance and testing | D15: This document specifies the framework, concepts and methodology for conformance testing and criteria to be achieved to claim conformance to the family of applicable standardization documents regarding geographic information and relevant application domains. This document provides a framework for specifying abstract test suites composed of abstract test cases grouped in conformance classes and for defining the procedures to be followed during conformance testing. Conformance can be claimed for data or software products or services or by specifications including any profile or functional standard. The structure of, and relationships between, conformance classes as defined in this document underly a systematic approach to configuration management involving managing dependencies within and between modules. | F15: https://www.iso.org/standard/76457.html | G15: 2005.01 | H15: 2022.07 | J15: 35.240.70 | L15: Yes | M15: CEN/TC 287 | N15: Yes | O15: ISO/TC 211 | P15: =INDEX(Colours!$C$2:$C$14,MATCH(K15,Colours!$A$2:$A$14,0)) -> #N/A | T15: =3+TableStandards11[[#This Row],[Degree Centrality]]*17 -> 3
A16: 15 | B16: ISO 19106 | C16: Geographic information - Profiles | D16: This International Standard is intended to define the concept of a profile of the ISO geographic information standards developed by ISO/TC 211 and to provide guidance for the creation of such profiles. Only those components of specifications that meet the definition of a profile contained herein can be established and managed through the mechanisms described in this International Standard. | F16: https://www.iso.org/standard/26011.html | G16: 2006.03 | H16: 2006.03 | J16: 35.240.70 | L16: Yes | M16: CEN/TC 287 | N16: Yes | O16: ISO/TC 211 | P16: =INDEX(Colours!$C$2:$C$14,MATCH(K16,Colours!$A$2:$A$14,0)) -> #N/A | T16: =3+TableStandards11[[#This Row],[Degree Centrality]]*17 -> 3
A17: 16 | B17: ISO 19107 | C17: Geographic information - Spatial schema | D17: This document specifies conceptual schemas for describing the spatial characteristics of geographic entities, and a set of spatial operations consistent with these schemas. It treats "vector" geometry and topology. It defines standard spatial operations for use in access, query, management, processing and data exchange of geographic information for spatial (geometric and topological) objects. Because of the nature of geographic information, these geometric coordinate spaces will normally have up to three spatial dimensions, one temporal dimension and any number of other spatially dependent parameters as needed by the applications. In general, the topological dimension of the spatial projections of the geometric objects will be at most three. | F17: https://www.iso.org/standard/66175.html | G17: 2005.01 | H17: 2019.12 | J17: 35.240.70 | L17: Yes | M17: CEN/TC 287 | N17: Yes | O17: ISO/TC 211 | P17: =INDEX(Colours!$C$2:$C$14,MATCH(K17,Colours!$A$2:$A$14,0)) -> #N/A | T17: =3+TableStandards11[[#This Row],[Degree Centrality]]*17 -> 3
A18: 17 | B18: ISO 19108 | C18: Geographic information - Temporal schema | D18: This International Standard defines concepts for describing temporal characteristics of geographic information. It depends upon existing information technology standards for the interchange of temporal information. It provides a basis for defining temporal feature attributes, feature operations, and feature associations, and for defining the temporal aspects of metadata about geographic information. Since this International Standard is concerned with the temporal characteristics of geographic information as they are abstracted from the real world, it emphasizes valid time rather than transaction time. | F18: https://www.iso.org/standard/26013.html | G18: 2005.01 | H18: 2005.01 | I18: 06.2008 | J18: 35.240.70 | L18: Yes | M18: CEN/TC 287 | N18: Yes | O18: ISO/TC 211 | P18: =INDEX(Colours!$C$2:$C$14,MATCH(K18,Colours!$A$2:$A$14,0)) -> #N/A | T18: =3+TableStandards11[[#This Row],[Degree Centrality]]*17 -> 3
A19: 18 | B19: ISO 19109 | C19: Geographic information - General feature model and rules for application schema | D19: This document defines the General Feature Model (GFM) as the metamodel for creating application schemas in the context of geo-information modelling. The GFM is explained and implemented as rules for creating and documenting application schemas, including principles for the definition of features. This document is applicable to: — conceptual modelling of features and their properties from a universe of discourse; — definition of application schemas; — general rules for using a conceptual schema language for application schemas; — rules for application schemas using UML as the conceptual schema language; — transition from the concepts in the conceptual model to the data types in the application schema; — integration of standardized schemas from other ISO geographic information standards with the application schema. This document does not apply to: — choice of one particular conceptual schema language for application schemas; — definition of any particular application schemas; — representation of feature types and their properties in a feature catalogue; — representation of metadata; — rules for mapping one application schema to another; — implementation of the application schema in a computer environment; — computer system and application software design; — programming. | F19: https://www.iso.org/standard/84700.html | G19: 2015.12 | H19: 2025.07 | J19: 35.240.70 | L19: Yes | M19: CEN/TC 287 | N19: Yes | O19: ISO/TC 211 | P19: =INDEX(Colours!$C$2:$C$14,MATCH(K19,Colours!$A$2:$A$14,0)) -> #N/A | T19: =3+TableStandards11[[#This Row],[Degree Centrality]]*17 -> 3
A20: 19 | B20: ISO 19110 | C20: Geographic information - Methodology for feature cataloguing | D20: ISO 19110:2016 defines the methodology for cataloguing feature types. This document specifies how feature types can be organized into a feature catalogue and presented to the users of a set of geographic data. This document is applicable to creating catalogues of feature types in previously uncatalogued domains and to revising existing feature catalogues to comply with standard practice. This document applies to the cataloguing of feature types that are represented in digital form. Its principles can be extended to the cataloguing of other forms of geographic data. Feature catalogues are independent of feature concept dictionaries defined in ISO 19126 and can be specified without having to use or create a Feature Concept Dictionary. ISO 19110:2016 is applicable to the definition of geographic features at the type level. This document is not applicable to the representation of individual instances of each type. This document excludes portrayal schemas as specified in ISO 19117. ISO 19110:2016 may be used as a basis for defining the universe of discourse being modelled in a particular application, or to standardize general aspects of real world features being modelled in more than one application. | F20: https://www.iso.org/standard/57303.html | G20: 2006.07 | H20: 2016.07 | J20: 35.240.70 | L20: Yes | M20: CEN/TC 287 | N20: Yes | O20: ISO/TC 211 | P20: =INDEX(Colours!$C$2:$C$14,MATCH(K20,Colours!$A$2:$A$14,0)) -> #N/A | T20: =3+TableStandards11[[#This Row],[Degree Centrality]]*17 -> 3
A21: 20 | B21: ISO 19111 | C21: Geographic information - Referencing by coordinates | D21: This document defines the conceptual schema for the description of referencing by coordinates. It describes the minimum data required to define coordinate reference systems. This document supports the definition of: — spatial coordinate reference systems where coordinate values do not change with time. The system may: — be geodetic and apply on a national or regional basis, or — apply locally such as for a building or construction site, or — apply locally to an image or image sensor; — be referenced to a moving platform such as a car, a ship, an aircraft or a spacecraft. Such a coordinate reference system can be related to a second coordinate reference system which is referenced to the Earth through a transformation that includes a time element; — spatial coordinate reference systems in which coordinate values of points on or near the surface of the earth change with time due to tectonic plate motion or other crustal deformation. Such dynamic systems include time evolution, however they remain spatial in nature; — parametric coordinate reference systems which use a non-spatial parameter that varies monotonically with height or depth; — temporal coordinate reference systems which use dateTime, temporal count or temporal measure quantities that vary monotonically with time; — mixed spatial, parametric or temporal coordinate reference systems. The definition of a coordinate reference system does not change with time, although in some cases some of the defining parameters can include a rate of change of the parameter. The coordinate values within a dynamic and in a temporal coordinate reference system can change with time. This document also describes the conceptual schema for defining the information required to describe operations that change coordinate values. In addition to the minimum data required for the definition of the coordinate reference system or coordinate operation, the conceptual schema allows additional descriptive information - coordinate reference system metadata - to be provided. This document is applicable to producers and users of geographic information. Although it is applicable to digital geographic data, the principles described in this document can be extended to many other forms of spatial data such as maps, charts and text documents. | F21: https://www.iso.org/standard/74039.html | G21: 2007.07 | H21: 2020.03 | I21: 08.2023 | J21: 35.240.70 | L21: Yes | M21: CEN/TC 287 | N21: Yes | O21: ISO/TC 211 | P21: =INDEX(Colours!$C$2:$C$14,MATCH(K21,Colours!$A$2:$A$14,0)) -> #N/A | T21: =3+TableStandards11[[#This Row],[Degree Centrality]]*17 -> 3
A22: 21 | B22: ISO 19112 | C22: Geographic information - Spatial referencing by geographic identifiers | D22: This document defines the conceptual schema for spatial references based on geographic identifiers. It establishes a general model for spatial referencing using geographic identifiers and defines the components of a spatial reference system. It also specifies a conceptual scheme for a gazetteer. Spatial referencing by coordinates is addressed in ISO 19111. However, a mechanism for recording complementary coordinate references is included in this document. This document enables producers of data to define spatial reference systems using geographic identifiers and assists users in understanding the spatial references used in datasets. It enables gazetteers to be constructed in a consistent manner and supports the development of other standards in the field of geographic information. This document is applicable to digital geographic data, and its principles may be extended to other forms of geographic data such as maps, charts and textual documents. | F22: https://www.iso.org/standard/70742.html | G22: 2005.01 | H22: 2019.03 | J22: 35.240.70 | L22: Yes | M22: CEN/TC 287 | N22: Yes | O22: ISO/TC 211 | P22: =INDEX(Colours!$C$2:$C$14,MATCH(K22,Colours!$A$2:$A$14,0)) -> #N/A | T22: =3+TableStandards11[[#This Row],[Degree Centrality]]*17 -> 3
A23: 22 | B23: ISO 19115-1 | C23: Geographic information - Metadata - Part 1: Fundamentals | D23: This International Standard defines the schema required for describing geographic information and services by means of metadata. It provides information about the identification, the extent, the quality, the spatial and temporal aspects, the content, the spatial reference, the portrayal, distribution, and other properties of digital geographic data and services. This International Standard is applicable to: - the cataloguing of all types of resources, clearinghouse activities, and the full description of datasets and services; - geographic services, geographic datasets, dataset series, and individual geographic features and feature properties. This International Standard defines: - mandatory and conditional metadata sections, metadata entities, and metadata elements; - the minimum set of metadata required to serve the full range of metadata applications (data discovery, determining data fitness for use, data access, data transfer, and use of digital data and services); - optional metadata elements – to allow for a more extensive standard description of resources, if required; - a method for extending metadata to fit specialized needs. Though this International Standard is applicable to digital data and services, its principles can be extended to many other types of resources such as maps, charts, and textual documents as well as non-geographic data. Certain conditional metadata elements may not apply to these other forms of data. | F23: https://www.iso.org/standard/53798.html | G23: 2005.01 | H23: 2014.04 | I23: 12.2020 | J23: 35.240.70 | L23: Yes | M23: CEN/TC 287 | N23: Yes | O23: ISO/TC 211 | P23: =INDEX(Colours!$C$2:$C$14,MATCH(K23,Colours!$A$2:$A$14,0)) -> #N/A | T23: =3+TableStandards11[[#This Row],[Degree Centrality]]*17 -> 3
A24: 23 | B24: ISO 19115-2 | C24: Geographic information - Metadata - Part 2: Extensions for acquisition and processing | D24: This document extends ISO 19115-1:2014 by defining the schema required for an enhanced description of the acquisition and processing of geographic information, including imagery. Included are the properties of measuring systems and the numerical methods and computational procedures used to derive geographic information from the data acquired by them. This document also provides the XML encoding for acquisition and processing metadata thereby extending the XML schemas defined in ISO/TS 19115-3. | F24: https://www.iso.org/standard/67039.html | G24: 2010.01 | H24: 2019.02 | I24: 03.2022 | J24: 35.240.70 | L24: Yes | M24: CEN/TC 287 | N24: Yes | O24: ISO/TC 211 | P24: =INDEX(Colours!$C$2:$C$14,MATCH(K24,Colours!$A$2:$A$14,0)) -> #N/A | T24: =3+TableStandards11[[#This Row],[Degree Centrality]]*17 -> 3
A25: 24 | B25: ISO 19115-3 | C25: Geographic information - Metadata - Part 3: XML schema implementation for fundamental concepts | D25: This document defines an integrated XML implementation of ISO 19115-1 and ISO 19115-2 by defining the following artefacts: — a set of XML schema required to validate metadata instance documents conforming to conceptual model elements defined in ISO 19115-1 and ISO 19115-2; and — a set of ISO/IEC 19757-3 (Schematron) rules that implement validation constraints in the ISO 19115-1 and ISO 19115-2 UML models that are not validated by the XML schema. This document describes the procedure used to generate XML schemas from ISO geographic information conceptual models related to metadata. The XML schemas are generated directly from the conceptual UML model (8.5). | F25: https://www.iso.org/standard/80874.html | G25: 2023.08 | H25: 2023.08 | J25: 35.240.70 | L25: Yes | M25: CEN/TC 287 | N25: Yes | O25: ISO/TC 211 | P25: =INDEX(Colours!$C$2:$C$14,MATCH(K25,Colours!$A$2:$A$14,0)) -> #N/A | T25: =3+TableStandards11[[#This Row],[Degree Centrality]]*17 -> 3
A26: 25 | B26: ISO 19116 | C26: Geographic information - Positioning services | D26: This document specifies the data structure and content of an interface that permits communication between position-providing device(s) and position-using device(s) enabling the position-using device(s) to obtain and unambiguously interpret position information and determine, based on a measure of the degree of reliability, whether the resulting position information meets the requirements of the intended use. A standardized interface for positioning allows the integration of reliable position information obtained from non-specific positioning technologies and is useful in various location-focused information applications, such as surveying, navigation, intelligent transportation systems (ITS) and location-based services (LBS). | F26: https://www.iso.org/standard/87480.html | G26: 2019.12 | H26: 2025.04 | J26: 35.240.70 | L26: Yes | M26: CEN/TC 287 | N26: Yes | O26: ISO/TC 211 | P26: =INDEX(Colours!$C$2:$C$14,MATCH(K26,Colours!$A$2:$A$14,0)) -> #N/A | T26: =3+TableStandards11[[#This Row],[Degree Centrality]]*17 -> 3
A27: 26 | B27: ISO 19117 | C27: Geographic information - Portrayal | D27: ISO 19117:2012 specifies a conceptual schema for describing symbols, portrayal functions that map geospatial features to symbols, and the collection of symbols and portrayal functions into portrayal catalogues. This conceptual schema can be used in the design of portrayal systems. It allows feature data to be separate from portrayal data, permitting data to be portrayed in a dataset independent manner. | F27: https://www.iso.org/standard/46226.html | G27: 2006.07 | H27: 2014.03 | J27: 35.240.70 | L27: Yes | M27: CEN/TC 287 | N27: Yes | O27: ISO/TC 211 | P27: =INDEX(Colours!$C$2:$C$14,MATCH(K27,Colours!$A$2:$A$14,0)) -> #N/A | T27: =3+TableStandards11[[#This Row],[Degree Centrality]]*17 -> 3
A28: 27 | B28: ISO 19118 | C28: Geographic information - Encoding | D28: This International Standard specifies the requirements for defining encoding rules for use for the interchange of data that conform to the geographic information in the set of International Standards known as the “ISO 19100 series”. This International Standard specifies - requirements for creating encoding rules based on UML schemas, - requirements for creating encoding services, and - requirements for XML-based encoding rules for neutral interchange of data. This International Standard does not specify any digital media, does not define any transfer services or transfer protocols, nor does it specify how to encode inline large images. | F28: https://www.iso.org/standard/44212.html | G28: 2006.07 | H28: 2011.10 | J28: 35.240.70 | L28: Yes | M28: CEN/TC 287 | N28: Yes | O28: ISO/TC 211 | P28: =INDEX(Colours!$C$2:$C$14,MATCH(K28,Colours!$A$2:$A$14,0)) -> #N/A | T28: =3+TableStandards11[[#This Row],[Degree Centrality]]*17 -> 3
A29: 28 | B29: ISO 19119 | C29: Geographic information - Services | D29: This International Standard defines requirements for how platform neutral and platform specific specification of services shall be created, in order to allow for one service to be specified independently of one or more underlying distributed computing platforms. This International Standard defines requirements for a further mapping from platform neutral to platform specific service specifications, in order to enable conformant and interoperable service implementations. This International Standard addresses the Meta:Service foundation of the ISO geographic information reference model described in ISO 19101-1:2014, Clause 6 and Clause 8, respectively. This International Standard defines how geographic services shall be categorised according to a service taxonomy based on architectural areas and allows also for services to be categorised according to a usage life cycle perspective, as well as according to domain specific and user defined service taxonomies, providing support for easier publication and discovery of services. | F29: https://www.iso.org/standard/59221.html | G29: 2006.06 | H29: 2016.02 | J29: 35.240.70 | L29: Yes | M29: CEN/TC 287 | N29: Yes | O29: ISO/TC 211 | P29: =INDEX(Colours!$C$2:$C$14,MATCH(K29,Colours!$A$2:$A$14,0)) -> #N/A | T29: =3+TableStandards11[[#This Row],[Degree Centrality]]*17 -> 3
A30: 29 | B30: ISO 19123-1 | C30: Geographic information - Schema for coverage geometry and functions - Part 1: Fundamentals | D30: This document defines a conceptual schema for coverages. A coverage is a mapping from a spatial, temporal or spatiotemporal domain to attribute values sharing the same attribute type. A coverage domain consists of a collection of direct positions in a coordinate space that can be defined in terms of spatial and/or temporal dimensions, as well as non-spatiotemporal (in ISO 19111:2019, “parametric”) dimensions. Examples of coverages include point clouds, grids, meshes, triangulated irregular networks, and polygon sets. Coverages are the prevailing data structures in a number of application areas, such as remote sensing, meteorology and mapping of depth, elevation, soil and vegetation. This document defines the coverage concept including the relationship between the domain of a coverage and its associated attribute range. This document defines the characteristics of the domain. The characteristics of the attribute range are not defined in this document, but are defined in implementation standards. Consequently, the standardization target of this document consists of implementation standards, not concrete implementations themselves. | F30: https://www.iso.org/standard/70743.html | G30: 2007.03 | H30: 2023.07 | J30: 35.240.70 | L30: Yes | M30: CEN/TC 287 | N30: Yes | O30: ISO/TC 211 | P30: =INDEX(Colours!$C$2:$C$14,MATCH(K30,Colours!$A$2:$A$14,0)) -> #N/A | T30: =3+TableStandards11[[#This Row],[Degree Centrality]]*17 -> 3
A31: 30 | B31: ISO 19123-2 | C31: Geographic information -- Schema for coverage geometry and functions -- Part 2: Coverage implementation schema | D31: This document specifies a concrete[1] implementable, conformance-testable coverage structure based on the abstract schema for coverages defined in the ISO 19123 schema for coverage geometry. This document defines a structure that is suitable for encoding in many encoding formats. [1] "concrete" is used here as a contrast to "abstract" in the sense described in the Introduction. | F31: https://www.iso.org/standard/70948.html | G31: 2018.10 | H31: 2018.10 | J31: 35.240.70 | L31: No | M31: n/a | N31: Yes | O31: ISO/TC 211 | P31: =INDEX(Colours!$C$2:$C$14,MATCH(K31,Colours!$A$2:$A$14,0)) -> #N/A | T31: =3+TableStandards11[[#This Row],[Degree Centrality]]*17 -> 3
A32: 31 | B32: ISO 19123-3 | C32: Geographic information - Schema for coverage geometry and functions - Part 3: Processing fundamentals | D32: This document defines a coverage processing language for server-side extraction, filtering, processing, analytics, and fusion of multi-dimensional geospatial coverages representing, for example, spatio-temporal sensor, image, simulation, or statistics datacubes. Services implementing this language provide access to original or derived sets of coverage information, in forms that are useful for client-side consumption. This document relies on the ISO 19123-1 abstract coverage model. In this edition, regular and irregular multi-dimensional grids are supported for axes that can carry spatial, temporal or any other semantics. Future editions will additionally support further axis types as well as further coverage types from ISO 19123-1, specifically, point clouds and meshes. | F32: https://www.iso.org/standard/83611.html | G32: 2023.07 | H32: 2023.07 | J32: 35.240.70 | L32: Yes | M32: CEN/TC 287 | N32: Yes | O32: ISO/TC 211 | P32: =INDEX(Colours!$C$2:$C$14,MATCH(K32,Colours!$A$2:$A$14,0)) -> #N/A | T32: =3+TableStandards11[[#This Row],[Degree Centrality]]*17 -> 3
A33: 32 | B33: ISO 19125-1 | C33: Geographic information - Simple feature access - Part 1: Common architecture | D33: This part of ISO 19125 establishes a common architecture and defines terms to use within the architecture.This part of ISO 19125 does not attempt to standardize and does not depend upon any part of the mechanism by which Types are added and maintained, including the following: a) syntax and functionality provided for defining types; b) syntax and functionality provided for defining functions; | F33: https://www.iso.org/standard/40114.html | G33: 2006.03 | H33: 2006.03 | J33: 35.240.70 | L33: Yes | M33: CEN/TC 287 | N33: Yes | O33: ISO/TC 211 | P33: =INDEX(Colours!$C$2:$C$14,MATCH(K33,Colours!$A$2:$A$14,0)) -> #N/A | T33: =3+TableStandards11[[#This Row],[Degree Centrality]]*17 -> 3
A34: 33 | B34: ISO 19126 | C34: Geographic information - Feature concept dictionaries and registers | D34: This document specifies a schema for feature concept dictionaries to be established and managed as registers. It does not specify schemas for feature catalogues or for the management of feature catalogues as registers. However, as feature catalogues are often derived from feature concept dictionaries, this document does specify a schema for a hierarchical register of feature concept dictionaries and feature catalogues. These registers are in accordance with ISO 19135‑1. | F34: https://www.iso.org/standard/78898.html | G34: 2009.11 | H34: 2021.06 | J34: 35.240.70 | L34: Yes | M34: CEN/TC 287 | N34: Yes | O34: ISO/TC 211 | P34: =INDEX(Colours!$C$2:$C$14,MATCH(K34,Colours!$A$2:$A$14,0)) -> #N/A | T34: =3+TableStandards11[[#This Row],[Degree Centrality]]*17 -> 3
A35: 34 | B35: ISO 19127 | C35: Geographic information -- Geodetic register | D35: This document defines the management and operations of the ISO geodetic register and identifies the data elements, in accordance with ISO 19111:2007 and the core schema within ISO 19135-1:2015, required within the geodetic register. | F35: https://www.iso.org/standard/67252.html | G35: 2005.06 | H35: 2019.02 | J35: 35.240.70; 07.040 | L35: No | M35: n/a | N35: Yes | O35: ISO/TC 211 | P35: =INDEX(Colours!$C$2:$C$14,MATCH(K35,Colours!$A$2:$A$14,0)) -> #N/A | T35: =3+TableStandards11[[#This Row],[Degree Centrality]]*17 -> 3
A36: 35 | B36: ISO 19128 | C36: Geographic information - Web map server interface | D36: This International Standard specifies the behaviour of a service that produces spatially referenced maps dynamically from geographic information. It specifies operations to retrieve a description of the maps offered by a server to retrieve a map, and to query a server about features displayed on a map. This International Standard is applicable to pictorial renderings of maps in a graphical format; it is not applicable to retrieval of actual feature data or coverage data values. | F36: https://www.iso.org/standard/32546.html | G36: 2008.01 | H36: 2008.01 | J36: 35.240.70 | L36: Yes | M36: CEN/TC 287 | N36: Yes | O36: ISO/TC 211 | P36: =INDEX(Colours!$C$2:$C$14,MATCH(K36,Colours!$A$2:$A$14,0)) -> #N/A | T36: =3+TableStandards11[[#This Row],[Degree Centrality]]*17 -> 3
... A41: 40 | B41: ISO 19134 | C41: Geographic information - Location-based services - Multimodal routing and navigation | D41: This International Standard specifies the data types and their associated operations for the implementation of multimodal location-based services for routing and navigation. It is designed to specify web services that may be made available to wireless devices through web-resident proxy applications, but is not limited to that environment. | F41: https://www.iso.org/standard/32552.html | G41: 2008.08 | H41: 2008.08 | J41: 35.240.70 | L41: Yes | M41: CEN/TC 287 | N41: Yes | O41: ISO/TC 211 | P41: =INDEX(Colours!$C$2:$C$14,MATCH(K41,Colours!$A$2:$A$14,0)) -> #N/A | T41: =3+TableStandards11[[#This Row],[Degree Centrality]]*17 -> 3
A42: 41 | B42: ISO 19135-1 | C42: Geographic information - Procedures for item registration - Part 1: Fundamentals | D42: This part of ISO 19135 specifies procedures to be followed in establishing, maintaining, and publishing registers of unique, unambiguous, and permanent identifiers and meanings that are assigned to items of geographic information. In order to accomplish this purpose, this part of ISO 19135 specifies elements that are necessary to manage the registration of these items. | F42: https://www.iso.org/standard/54721.html | G42: 2007.03 | H42: 2015.11 | I42: 03.2021 | J42: 35.240.70 | L42: Yes | M42: CEN/TC 287 | N42: Yes | O42: ISO/TC 211 | P42: =INDEX(Colours!$C$2:$C$14,MATCH(K42,Colours!$A$2:$A$14,0)) -> #N/A | T42: =3+TableStandards11[[#This Row],[Degree Centrality]]*17 -> 3
A43: 42 | B43: ISO 19136-1 | C43: Geographic information - Geography Markup Language (GML) - Part 1: Fundamentals | D43: The Geography Markup Language (GML) is an XML encoding in accordance with ISO 19118 for the transport and storage of geographic information modelled in accordance with the conceptual modelling framework used in the ISO 19100 series of International Standards and including both the spatial and non-spatial properties of geographic features. This document defines the XML Schema syntax, mechanisms and conventions that: — provide an open, vendor-neutral framework for the description of geospatial application schemas for the transport and storage of geographic information in XML; — allow profiles that support proper subsets of GML framework descriptive capabilities; — support the description of geospatial application schemas for specialized domains and information communities; — enable the creation and maintenance of linked geographic application schemas and datasets; — support the storage and transport of application schemas and datasets; — increase the ability of organizations to share geographic application schemas and the information they describe. Implementers can decide to store geographic application schemas and information in GML, or they can decide to convert from some other storage format on demand and use GML only for schema and data transport. NOTE If an ISO 19109 conformant application schema described in UML is used as the basis for the storage and transportation of geographic information, this document provides normative rules for the mapping of such an application schema to a GML application schema in XML Schema and, as such, to an XML encoding for data with a logical structure in accordance with the ISO 19109 conformant application schema. | F43: https://www.iso.org/standard/75676.html | G43: 2009.03 | H43: 2020.04 | J43: 35.240.70 | L43: Yes | M43: CEN/TC 287 | N43: Yes | O43: ISO/TC 211 | P43: =INDEX(Colours!$C$2:$C$14,MATCH(K43,Colours!$A$2:$A$14,0)) -> #N/A | T43: =3+TableStandards11[[#This Row],[Degree Centrality]]*17 -> 3
A44: 43 | B44: ISO 19136-2 | C44: Geographic information - Geography Markup Language (GML) - Part 2: Extended schemas and encoding rules | D44: The Geography Markup Language (GML) is an XML encoding in compliance with ISO 19118 for the transport and storage of geographic information modelled in accordance with the conceptual modelling framework used in the ISO 19100‑ series of International Standards and including both the spatial and non-spatial properties of geographic features. ISO 19136-2:2015 defines the XML Schema syntax, mechanisms and conventions that: -provide an open, vendor-neutral framework for the description of geospatial application schemas for the transport and storage of geographic information in XML; -allow profiles that support proper subsets of GML framework descriptive capabilities; -support the description of geospatial application schemas for specialized domains and information communities; -enable the creation and maintenance of linked geographic application schemas and datasets; -support the storage and transport of application schemas and datasets; -increase the ability of organizations to share geographic application schemas and the information they describe. Implementers may decide to store geographic application schemas and information in GML, or they may decide to convert from some other storage format on demand and use GML only for schema and data transport. ISO 19136-2:2015 builds on ISO 19136:2007 (GML 3.2), and extends it with additional schema components and requirements. NOTE If an ISO 19109 conformant application schema described in UML is used as the basis for the storage and transportation of geographic information, this part of ISO 19136 provides normative rules for the mapping of such an application schema to a GML application schema in XML Schema and, as such, to an XML encoding for data with a logical structure in accordance with the ISO 19109 conformant application schema. | F44: https://www.iso.org/standard/61585.html | G44: 2009.03 | H44: 2018.09 | J44: 35.240.70 | L44: Yes | M44: CEN/TC 287 | N44: Yes | O44: ISO/TC 211 | P44: =INDEX(Colours!$C$2:$C$14,MATCH(K44,Colours!$A$2:$A$14,0)) -> #N/A | T44: =3+TableStandards11[[#This Row],[Degree Centrality]]*17 -> 3
...

Sheet GIS-Relationships
A1: Id | B1: Source Standard Number | C1: Target Current Number | D1: Target NonCurrent Number | E1: Target First Year | F1: Target Current Year | G1: ICS | H1: Source Calculation | I1: Target Calculation | J1: Source Colour | K1: Target Colour | L1: Type | M1: Link | N1: Source Type | O1: Target Type | P1: Inter-BIM Relationship | Q1: Weight _calculation | R1: Rank Pedro | S1: Weight Pedro_calculation | T1: Category | U1: Category Colour | V1: timeset_calculation | W1: Colour_calculation | X1: Label
A2: 1 | B2: CEN ISO/TS 19139-1 | C2: GIS anchor | E2: 2007.04 | F2: 2019.03 | G2: 35.240.70 | H2: =INDEX('GIS-Standards'!$A$2:$A$305,MATCH(B2,'GIS-Standards'!$B$2:$B$305,0)) -> #N/A | I2: =INDEX('GIS-Standards'!$A$2:$A$305,MATCH(C2,'GIS-Standards'!$B$2:$B$305,0)) -> #N/A | J2: =INDEX('GIS-Standards'!$O$2:$O$305,MATCH(B2,'GIS-Standards'!$B$2:$B$305,0)) -> #N/A | K2: =INDEX('GIS-Standards'!$O$2:$O$305,MATCH(C2,'GIS-Standards'!$B$2:$B$305,0)) -> #N/A | M2: Anchor | N2: =INDEX('GIS-Standards'!$I$2:$I$305,MATCH(B2,'GIS-Standards'!$B$2:$B$305,0)) -> #N/A | O2: =INDEX('GIS-Standards'!$I$2:$I$305,MATCH(C2,'GIS-Standards'!$B$2:$B$305,0)) -> #N/A | P2: =AND(TableRelationships12[[#This Row],[Source Type]]="BIM",TableRelationships12[[#This Row],[Target Type]]="BIM") -> #N/A | Q2: =IF(M2="Normative",6,IF(M2="Secondary",4,IF(M2="Anchor",2,1))) -> 2 | S2: =IF(R2="High",10,IF(R2="Medium",6,IF(R2="Low",2,1))) -> 1 | T2: =IF(TableRelationships12[[#This Row],[Rank Pedro]]="Low","linkCategory1",IF(TableRelationships12[[#This Row],[Rank Pedro]]="Medium","linkCategory2",IF(TableRelationships12[[#This Row],[Rank Pedro]]="High","linkCategory3",""))) | U2: =IF(TableRelationships12[[#This Row],[Rank Pedro]]="Low","Pink",IF(TableRelationships12[[#This Row],[Rank Pedro]]="Medium","Purple",IF(TableRelationships12[[#This Row],[Rank Pedro]]="High","Brown",""))) | V2: =MAX(INDEX(Standards!$F$2:$F$296,MATCH(B2,Standards!$B$2:$B$296,0)),INDEX(Standards!$F$2:$F$296,MATCH(C2,Standards!$B$2:$B$296,0))) -> #N/A | W2: =IF(M2="Normative", "#d6bf2a", IF(M2="Informative", "#2f89d1", 1)) -> 1
A3: 2 | B3: CEN ISO/TS 19139-1 | C3: ISO 19118 | E3: 2005.07 | F3: 2011.1 | G3: 35.240.70 | H3: =INDEX('GIS-Standards'!$A$2:$A$305,MATCH(B3,'GIS-Standards'!$B$2:$B$305,0)) -> #N/A | I3: =INDEX('GIS-Standards'!$A$2:$A$305,MATCH(C3,'GIS-Standards'!$B$2:$B$305,0)) -> 27 | J3: =INDEX('GIS-Standards'!$O$2:$O$305,MATCH(B3,'GIS-Standards'!$B$2:$B$305,0)) -> #N/A | K3: =INDEX('GIS-Standards'!$O$2:$O$305,MATCH(C3,'GIS-Standards'!$B$2:$B$305,0)) -> ISO/TC 211 | M3: Normative | N3: =INDEX('GIS-Standards'!$I$2:$I$305,MATCH(B3,'GIS-Standards'!$B$2:$B$305,0)) -> #N/A | O3: =INDEX('GIS-Standards'!$I$2:$I$305,MATCH(C3,'GIS-Standards'!$B$2:$B$305,0)) -> 0 | P3: =AND(TableRelationships12[[#This Row],[Source Type]]="BIM",TableRelationships12[[#This Row],[Target Type]]="BIM") -> #N/A | Q3: =IF(M3="Normative",6,IF(M3="Secondary",4,IF(M3="Anchor",2,1))) -> 6 | S3: =IF(R3="High",10,IF(R3="Medium",6,IF(R3="Low",2,1))) -> 1 | T3: =IF(TableRelationships12[[#This Row],[Rank Pedro]]="Low","linkCategory1",IF(TableRelationships12[[#This Row],[Rank Pedro]]="Medium","linkCategory2",IF(TableRelationships12[[#This Row],[Rank Pedro]]="High","linkCategory3",""))) | U3: =IF(TableRelationships12[[#This Row],[Rank Pedro]]="Low","Pink",IF(TableRelationships12[[#This Row],[Rank Pedro]]="Medium","Purple",IF(TableRelationships12[[#This Row],[Rank Pedro]]="High","Brown",""))) | V3: =MAX(INDEX(Standards!$F$2:$F$296,MATCH(B3,Standards!$B$2:$B$296,0)),INDEX(Standards!$F$2:$F$296,MATCH(C3,Standards!$B$2:$B$296,0))) -> #N/A | W3: =IF(M3="Normative", "#d6bf2a", IF(M3="Informative", "#2f89d1", 1)) -> #d6bf2a
A4: 3 | B4: CEN ISO/TS 19139-1 | C4: W3C xml-names | H4: =INDEX('GIS-Standards'!$A$2:$A$305,MATCH(B4,'GIS-Standards'!$B$2:$B$305,0)) -> #N/A | I4: =INDEX('GIS-Standards'!$A$2:$A$305,MATCH(C4,'GIS-Standards'!$B$2:$B$305,0)) -> #N/A | J4: =INDEX('GIS-Standards'!$O$2:$O$305,MATCH(B4,'GIS-Standards'!$B$2:$B$305,0)) -> #N/A | K4: =INDEX('GIS-Standards'!$O$2:$O$305,MATCH(C4,'GIS-Standards'!$B$2:$B$305,0)) -> #N/A | M4: Normative | N4: =INDEX('GIS-Standards'!$I$2:$I$305,MATCH(B4,'GIS-Standards'!$B$2:$B$305,0)) -> #N/A | O4: =INDEX('GIS-Standards'!$I$2:$I$305,MATCH(C4,'GIS-Standards'!$B$2:$B$305,0)) -> #N/A | P4: =AND(TableRelationships12[[#This Row],[Source Type]]="BIM",TableRelationships12[[#This Row],[Target Type]]="BIM") -> #N/A | Q4: =IF(M4="Normative",6,IF(M4="Secondary",4,IF(M4="Anchor",2,1))) -> 6 | S4: =IF(R4="High",10,IF(R4="Medium",6,IF(R4="Low",2,1))) -> 1 | T4: =IF(TableRelationships12[[#This Row],[Rank Pedro]]="Low","linkCategory1",IF(TableRelationships12[[#This Row],[Rank Pedro]]="Medium","linkCategory2",IF(TableRelationships12[[#This Row],[Rank Pedro]]="High","linkCategory3",""))) | U4: =IF(TableRelationships12[[#This Row],[Rank Pedro]]="Low","Pink",IF(TableRelationships12[[#This Row],[Rank Pedro]]="Medium","Purple",IF(TableRelationships12[[#This Row],[Rank Pedro]]="High","Brown",""))) | V4: =MAX(INDEX(Standards!$F$2:$F$296,MATCH(B4,Standards!$B$2:$B$296,0)),INDEX(Standards!$F$2:$F$296,MATCH(C4,Standards!$B$2:$B$296,0))) -> #N/A | W4: =IF(M4="Normative", "#d6bf2a", IF(M4="Informative", "#2f89d1", 1)) -> #d6bf2a
